Workbook

Sheet 波次一（常温北京）
A1: 原线路号 | B1: 店铺代码 | C1: 店名 | D1: 预计到店时间 | E1: 冷藏时间
A2: 101 | B2: 394512 | C2: 超市发罗森北清路二店 | D2: 0.875 | E2: =_xlfn.XLOOKUP(B2,'波次二（低温北京）'!B:B,'波次二（低温北京）'!D:D) -> 0.0625
B3: 394234 | C3: 超市发罗森北清路店 | D3: 0.88888889 | E3: =_xlfn.XLOOKUP(B3,'波次二（低温北京）'!B:B,'波次二（低温北京）'!D:D) -> 0.076388889
B4: 394560 | C4: 超市发罗森北安河二店 | D4: 0.90972222 | E4: =_xlfn.XLOOKUP(B4,'波次二（低温北京）'!B:B,'波次二（低温北京）'!D:D) -> 0.097222222
B5: 394258 | C5: 超市发罗森北安河店 | D5: 0.93055556 | E5: =_xlfn.XLOOKUP(B5,'波次二（低温北京）'!B:B,'波次二（低温北京）'!D:D) -> 0.11805556
B6: 394070 | C6: 木荷路华为园区 | D6: 0.95833333 | E6: =_xlfn.XLOOKUP(B6,'波次二（低温北京）'!B:B,'波次二（低温北京）'!D:D) -> 0.14583333
B7: 394488 | C7: 超市发罗森太舟坞店 | D7: 0.97916667 | E7: =_xlfn.XLOOKUP(B7,'波次二（低温北京）'!B:B,'波次二（低温北京）'!D:D) -> 0.16666667
A8: 102 | B8: 398170 | C8: 昌平未来科学城未来中心店 | D8: 0.85416667 | E8: =_xlfn.XLOOKUP(B8,'波次二（低温北京）'!B:B,'波次二（低温北京）'!D:D) -> 0.083333333
B9: 398090 | C9: 超市发天通苑西区 | D9: 0.875 | E9: =_xlfn.XLOOKUP(B9,'波次二（低温北京）'!B:B,'波次二（低温北京）'!D:D) -> 0.10416667
B10: 392719 | C10: 金隅智造工场店新店 | D10: 0.89583333 | E10: =_xlfn.XLOOKUP(B10,'波次二（低温北京）'!B:B,'波次二（低温北京）'!D:D) -> 0.125
B11: 394510 | C11: 东升科技园店 | D11: 0.91666667 | E11: =_xlfn.XLOOKUP(B11,'波次二（低温北京）'!B:B,'波次二（低温北京）'!D:D) -> 0.14583333
B12: 394485 | C12: 永泰生活服务中心店 | D12: 0.9375 | E12: =_xlfn.XLOOKUP(B12,'波次二（低温北京）'!B:B,'波次二（低温北京）'!D:D) -> 0.16666667
A13: 103 | B13: 394096 | C13: 超市发农大 | D13: 0.875 | E13: =_xlfn.XLOOKUP(B13,'波次二（低温北京）'!B:B,'波次二（低温北京）'!D:D) -> 0.20138889
B14: 394038 | C14: 联想新园区 | D14: 0.90277778 | E14: =_xlfn.XLOOKUP(B14,'波次二（低温北京）'!B:B,'波次二（低温北京）'!D:D) -> 0.0625
B15: 394150 | C15: 网易研发中心 | D15: 0.91666667 | E15: =_xlfn.XLOOKUP(B15,'波次二（低温北京）'!B:B,'波次二（低温北京）'!D:D) -> 0.125
B16: 394110 | C16: 新浪总部大厦 | D16: 0.94791667 | E16: =_xlfn.XLOOKUP(B16,'波次二（低温北京）'!B:B,'波次二（低温北京）'!D:D) -> 0.15277778
B17: 392718 | C17: 腾讯北京总部店 | D17: 0.97916667 | E17: =_xlfn.XLOOKUP(B17,'波次二（低温北京）'!B:B,'波次二（低温北京）'!D:D) -> 0.18055556
A18: 107 | B18: 394620 | C18: 北京快手元中心店 | D18: 0.875 | E18: =_xlfn.XLOOKUP(B18,'波次二（低温北京）'!B:B,'波次二（低温北京）'!D:D) -> 0.0625
B19: 394069 | C19: 互联网创新中心 | D19: 0.90277778 | E19: =_xlfn.XLOOKUP(B19,'波次二（低温北京）'!B:B,'波次二（低温北京）'!D:D) -> 0.09375
B20: 394437 | C20: 超市发罗森清河店 | D20: 0.92361111 | E20: =_xlfn.XLOOKUP(B20,'波次二（低温北京）'!B:B,'波次二（低温北京）'!D:D) -> 0.125
B21: 394089 | C21: 超市发上地 | D21: 0.94791667 | E21: =_xlfn.XLOOKUP(B21,'波次二（低温北京）'!B:B,'波次二（低温北京）'!D:D) -> 0.13888889
B22: 393016 | C22: 奥林匹克公园 | D22: 0.97916667 | E22: =_xlfn.XLOOKUP(B22,'波次二（低温北京）'!B:B,'波次二（低温北京）'!D:D) -> 0.16666667
A23: 108 | B23: 394048 | C23: 海淀杏石口路 | D23: 0.875 | E23: =_xlfn.XLOOKUP(B23,'波次二（低温北京）'!B:B,'波次二（低温北京）'!D:D) -> 0.1875
B24: 394630 | C24: 超市发罗森四季青路店 | D24: 0.89583333 | E24: =_xlfn.XLOOKUP(B24,'波次二（低温北京）'!B:B,'波次二（低温北京）'!D:D) -> 0.16666667
B25: 394104 | C25: 超市发玉泉路 | D25: 0.91666667 | E25: =_xlfn.XLOOKUP(B25,'波次二（低温北京）'!B:B,'波次二（低温北京）'!D:D) -> 0.15277778
B26: 399569 | C26: 西长安中骏世界城店 | D26: 0.94791667 | E26: =_xlfn.XLOOKUP(B26,'波次二（低温北京）'!B:B,'波次二（低温北京）'!D:D) -> 0.11805556
B27: 399548 | C27: 北京中海大厦店 | D27: 0.96875 | E27: =_xlfn.XLOOKUP(B27,'波次二（低温北京）'!B:B,'波次二（低温北京）'!D:D) -> 0.13194444
B28: 391715 | C28: 石景山金隅科技大厦店 | D28: 0.98611111 | E28: =_xlfn.XLOOKUP(B28,'波次二（低温北京）'!B:B,'波次二（低温北京）'!D:D) -> 0.097222222
B29: 399670 | C29: 北京门头沟长安天街店 | D29: 0.010416667 | E29: =_xlfn.XLOOKUP(B29,'波次二（低温北京）'!B:B,'波次二（低温北京）'!D:D) -> 0.076388889
A30: 109 | B30: 393067 | C30: 望京北望金辉大厦 | D30: 0.84722222 | E30: =_xlfn.XLOOKUP(B30,'波次二（低温北京）'!B:B,'波次二（低温北京）'!D:D) -> 0.0625
B31: 393303 | C31: 利星行中心二店 | D31: 0.875 | E31: =_xlfn.XLOOKUP(B31,'波次二（低温北京）'!B:B,'波次二（低温北京）'!D:D) -> 0.097222222
B32: 393206 | C32: 东亚望京中心店 | D32: 0.90277778 | E32: =_xlfn.XLOOKUP(B32,'波次二（低温北京）'!B:B,'波次二（低温北京）'!D:D) -> 0.11111111
B33: 393557 | C33: 北京鸿懋商务大厦店 | D33: 0.92361111 | E33: =_xlfn.XLOOKUP(B33,'波次二（低温北京）'!B:B,'波次二（低温北京）'!D:D) -> 0.13194444
B34: 394112 | C34: 超市发海淀大街 | D34: 0.95138889 | E34: =_xlfn.XLOOKUP(B34,'波次二（低温北京）'!B:B,'波次二（低温北京）'!D:D) -> 0.16666667
B35: 394062 | C35: 火器营地铁站 | D35: 0.96527778 | E35: =_xlfn.XLOOKUP(B35,'波次二（低温北京）'!B:B,'波次二（低温北京）'!D:D) -> 0.18055556
A36: 110 | B36: 392678 | C36: 北京地铁雍和宫站店 | D36: 0.875 | E36: =_xlfn.XLOOKUP(B36,'波次二（低温北京）'!B:B,'波次二（低温北京）'!D:D) -> 0.22916667
B37: 391001 | C37: 月坛北街 | D37: 0.89583333 | E37: =_xlfn.XLOOKUP(B37,'波次二（低温北京）'!B:B,'波次二（低温北京）'!D:D) -> 0.1875
B38: 394085 | C38: 超市发甘家口 | D38: 0.91666667 | E38: =_xlfn.XLOOKUP(B38,'波次二（低温北京）'!B:B,'波次二（低温北京）'!D:D) -> 0.16666667
B39: 394073 | C39: 超市发花园路 | D39: 0.9375 | E39: =_xlfn.XLOOKUP(B39,'波次二（低温北京）'!B:B,'波次二（低温北京）'!D:D) -> 0.14583333
B40: 394118 | C40: 超市发学院路超罗 | D40: 0.95833333 | E40: =_xlfn.XLOOKUP(B40,'波次二（低温北京）'!B:B,'波次二（低温北京）'!D:D) -> 0.125
...

Sheet 波次二（低温北京）
A1: 原线路号 | B1: 店铺代码 | C1: 店名 | D1: 预计到店时间
A2: 201 | B2: 394512 | C2: 超市发罗森北清路二店 | D2: 0.0625
B3: 394234 | C3: 超市发罗森北清路店 | D3: 0.076388889
B4: 394560 | C4: 超市发罗森北安河二店 | D4: 0.097222222
B5: 394258 | C5: 超市发罗森北安河店 | D5: 0.11805556
B6: 394070 | C6: 木荷路华为园区 | D6: 0.14583333
B7: 394488 | C7: 超市发罗森太舟坞店 | D7: 0.16666667
B8: 394526 | C8: 华为北研所K区店 | D8: 0.1875
B9: 393426 | C9: 北京地铁望京西站店 | D9: 0.22916667
A10: 202 | B10: 399722 | C10: 北京祥云小镇店 | D10: 0.0625
B11: 398170 | C11: 昌平未来科学城未来中心店 | D11: 0.083333333
B12: 398090 | C12: 超市发天通苑西区 | D12: 0.10416667
B13: 392719 | C13: 金隅智造工场店新店 | D13: 0.125
B14: 394510 | C14: 东升科技园店 | D14: 0.14583333
B15: 394485 | C15: 永泰生活服务中心店 | D15: 0.16666667
B16: 393720 | C16: 昌平新新公寓店 | D16: 0.20833333
B17: 398439 | C17: 北京地铁昌平站店 | D17: 0.22916667
A18: 203 | B18: 394038 | C18: 联想新园区 | D18: 0.0625
B19: 394069 | C19: 互联网创新中心 | D19: 0.09375
B20: 394150 | C20: 网易研发中心 | D20: 0.125
B21: 394110 | C21: 新浪总部大厦 | D21: 0.15277778
B22: 392718 | C22: 腾讯北京总部店 | D22: 0.18055556
B23: 394096 | C23: 超市发农大 | D23: 0.20138889
B24: 394489 | C24: 超市发罗森六里屯店 | D24: 0.21875
B25: 398689 | C25: 回龙观体育公园店 | D25: 0.22916667
B26: 393425 | C26: 北京地铁西土城店 | D26: 0.25
A27: 205 | B27: 396276 | C27: 京东总部1号店 | D27: 0.0625
B28: 393709 | C28: 京东总部2号院店 | D28: 0.083333333
B29: 395606 | C29: 福海公寓 | D29: 0.13888889
B30: 395470 | C30: 丰科中心店 | D30: 0.15277778
B31: 395017 | C31: 汉威国际广场 | D31: 0.16666667
B32: 393033 | C32: 四方桥东北侧店 | D32: 0.1875
B33: 392715 | C33: 北京地铁欢乐谷站店 | D33: 0.20833333
A34: 207 | B34: 394620 | C34: 北京快手元中心店 | D34: 0.0625
B35: 394123 | C35: 联想北研园楼大厦 | D35: 0.090277778
B36: 394122 | C36: 联想三标大厦 | D36: 0.10416667
B37: 394437 | C37: 超市发罗森清河店 | D37: 0.125
B38: 394089 | C38: 超市发上地 | D38: 0.13888889
B39: 393016 | C39: 奥林匹克公园 | D39: 0.16666667
B40: 394405 | C40: 北京地铁育新站店 | D40: 0.20138889
...

Sheet 波次三
A1: 原线路号 | B1: 店铺代码 | C1: 店名 | D1: 预计到店时间
A2: 125 | B2: 393046 | C2: 小天竺路 | D2: 0.00069444444
B3: 394705 | C3: 平谷步行街店 | D3: 0.041666667
B4: 409392 | C4: 天津市蓟州区天一绿海店 | D4: 0.083333333
B5: 467708 | C5: 三河文化艺术大街店 | D5: 0.125
A6: 126 | B6: 396449 | C6: 大兴国际氢能示范区店 | D6: 0.97916667
B7: 396495 | C7: 大兴南航总部基地店 | D7: 0.00069444444
B8: 396255 | C8: 东方航空公司总部店 | D8: 0.013888889
B9: 396141 | C9: 大兴星牌共享际 | D9: 0.034722222
B10: 396388 | C10: 北京鸿坤广场店 | D10: 0.055555556
A11: 127 | B11: 391721 | C11: 北京丽泽平安金融中心店 | D11: 0.00069444444
B12: 395302 | C12: 丽泽平安幸福中心店 | D12: 0.020833333
B13: 395092 | C13: 泥洼地铁站 | D13: 0.048611111
B14: 396058 | C14: 房山绿城百合 | D14: 0.090277778
B15: 396054 | C15: 良乡拱辰南大街 | D15: 0.13194444
B16: 396081 | C16: 房山燕化医院 | D16: 0.15277778
B17: 396053 | C17: 房山南大街 | D17: 0.1875
A18: 128 | B18: 466506 | C18: 廊坊燕郊诺亚大厦店 | D18: 0.00069444444
B19: 466697 | C19: 廊坊燕郊33号街区店 | D19: 0.020833333
B20: 466455 | C20: 廊坊燕郊尚京广场店 | D20: 0.041666667
B21: 461717 | C21: 廊坊燕郊夏威夷蓝湾店 | D21: 0.069444444
B22: 466370 | C22: 廊坊香河新开街店 | D22: 0.10416667
B23: 466435 | C23: 廊坊香河新华街店 | D23: 0.14583333
B24: 466653 | C24: 廊坊燕郊燕京理工学院店 | D24: 0.16666667
A25: 129 | B25: 397398 | C25: 北京地铁物资学院路站店 | D25: 0.1875
B26: 393399 | C26: 北京地铁草房站店 | D26: 0.22222222
B27: 393710 | C27: 北京地铁潘家园站店 | D27: 0.24305556
B28: 392716 | C28: 北京地铁角门西站店 | D28: 0.25
A29: 130 | B29: 395411 | C29: 北京地铁六里桥站店 | D29: 0.1875
B30: 395413 | C30: 北京地铁丰台科技园区站店 | D30: 0.20833333
B31: 395412 | C31: 北京地铁郭公庄站店 | D31: 0.22916667
B32: 392717 | C32: 北京地铁丰台站店 | D32: 0.23958333
A33: 132 | B33: 392710 | C33: 北京地铁3号线团结湖站店 | D33: 0.20833333
B34: 392408 | C34: 北京地铁安德里北街站店 | D34: 0.22916667
B35: 392713 | C35: 北京地铁什刹海站店 | D35: 0.23958333
A36: 133 | B36: 391718 | C36: 北京地铁12号线驼房营站店 | D36: 0.20138889
B37: 392708 | C37: 北京地铁3号线东坝站店 | D37: 0.22916667
B38: 392707 | C38: 北京地铁3号线朝阳站店 | D38: 0.25
A39: 150 | B39: 478610 | C39: 张家口职业技术学院店 | D39: 0
B40: 478648 | C40: 张家口乐享城店 | D40: 0.020833333
...

Sheet 波次四
A1: 原线路号 | B1: 店铺代码 | C1: 店名 | D1: 预计到店时间
A2: 240 | B2: 393151 | C2: 首都机场T3二层到达区外 | D2: 0.75
B3: 393152 | C3: 首都机场T3三层出发区东指廊 | D3: 0.75
B4: 393153 | C4: 首都机场T3三层出发区西指廊 | D4: 0.75
B5: 393155 | C5: 首都机场T3四层出发区外东 | D5: 0.75
B6: 393156 | C6: 首都机场T3D出发区 | D6: 0.75
B7: 393715 | C7: 首都国际机场T3四层出发层外西 | D7: 0.75
B8: 395710 | C8: 北京首都机场T3三层出发区北指廊店 | D8: 0.75
